<?xml version="1.0" encoding="UTF-8"?>
<!-- Generated by org.testng.reporters.JUnitReportReporter -->
<testsuite skipped="0" hostname="MCKL-20005142" name="restassuredapi.test.StaffUserService" tests="11" failures="2" timestamp="10 Mar 2022 05:39:03 GMT" time="168.496" errors="1">
  <testcase name="A_02_Test_invalid_token" time="1.685" classname="restassuredapi.test.StaffUserService"/>
  <testcase name="A_02_Test_invalid_token" time="1.723" classname="restassuredapi.test.StaffUserService"/>
  <testcase name="A_02_Test_invalid_token" time="0.953" classname="restassuredapi.test.StaffUserService">
    <failure type="java.lang.AssertionError" message="expected [200] but found [401]">
      <![CDATA[java.lang.AssertionError: expected [200] but found [401]
at org.testng.Assert.fail(Assert.java:96)
at org.testng.Assert.failNotEquals(Assert.java:776)
at org.testng.Assert.assertEqualsImpl(Assert.java:137)
at org.testng.Assert.assertEquals(Assert.java:118)
at org.testng.Assert.assertEquals(Assert.java:547)
at org.testng.Assert.assertEquals(Assert.java:557)
at restassuredapi.test.StaffUserService.BeforeMethod(StaffUserService.java:112)
at restassuredapi.test.StaffUserService.A_02_Test_invalid_token(StaffUserService.java:158)
at sun.reflect.NativeMethodAccessorImpl.invoke0(Native Method)
at sun.reflect.NativeMethodAccessorImpl.invoke(Unknown Source)
at sun.reflect.DelegatingMethodAccessorImpl.invoke(Unknown Source)
at java.lang.reflect.Method.invoke(Unknown Source)
at org.testng.internal.MethodInvocationHelper.invokeMethod(MethodInvocationHelper.java:124)
at org.testng.internal.Invoker.invokeMethod(Invoker.java:580)
at org.testng.internal.Invoker.invokeTestMethod(Invoker.java:716)
at org.testng.internal.Invoker.invokeTestMethods(Invoker.java:988)
at org.testng.internal.TestMethodWorker.invokeTestMethods(TestMethodWorker.java:125)
at org.testng.internal.TestMethodWorker.run(TestMethodWorker.java:109)
at org.testng.TestRunner.privateRun(TestRunner.java:648)
at org.testng.TestRunner.run(TestRunner.java:505)
at org.testng.SuiteRunner.runTest(SuiteRunner.java:455)
at org.testng.SuiteRunner.runSequentially(SuiteRunner.java:450)
at org.testng.SuiteRunner.privateRun(SuiteRunner.java:415)
at org.testng.SuiteRunner.run(SuiteRunner.java:364)
at org.testng.SuiteRunnerWorker.runSuite(SuiteRunnerWorker.java:52)
at org.testng.SuiteRunnerWorker.run(SuiteRunnerWorker.java:84)
at org.testng.TestNG.runSuitesSequentially(TestNG.java:1208)
at org.testng.TestNG.runSuitesLocally(TestNG.java:1137)
at org.testng.TestNG.runSuites(TestNG.java:1049)
at org.testng.TestNG.run(TestNG.java:1017)
at org.testng.remote.AbstractRemoteTestNG.run(AbstractRemoteTestNG.java:115)
at org.testng.remote.RemoteTestNG.initAndRun(RemoteTestNG.java:251)
at org.testng.remote.RemoteTestNG.main(RemoteTestNG.java:77)
]]>
    </failure>
  </testcase> <!-- A_02_Test_invalid_token -->
  <testcase name="A_02_Test_invalid_token" time="1.832" classname="restassuredapi.test.StaffUserService"/>
  <testcase name="A_01_Test_success" time="5.060" classname="restassuredapi.test.StaffUserService"/>
  <testcase name="A_02_Test_invalid_token" time="22.948" classname="restassuredapi.test.StaffUserService"/>
  <testcase name="A_01_Test_success" time="23.058" classname="restassuredapi.test.StaffUserService"/>
  <testcase name="A_01_Test_success" time="0.757" classname="restassuredapi.test.StaffUserService">
    <failure type="java.lang.AssertionError" message="expected [200] but found [401]">
      <![CDATA[java.lang.AssertionError: expected [200] but found [401]
at org.testng.Assert.fail(Assert.java:96)
at org.testng.Assert.failNotEquals(Assert.java:776)
at org.testng.Assert.assertEqualsImpl(Assert.java:137)
at org.testng.Assert.assertEquals(Assert.java:118)
at org.testng.Assert.assertEquals(Assert.java:547)
at org.testng.Assert.assertEquals(Assert.java:557)
at restassuredapi.test.StaffUserService.BeforeMethod(StaffUserService.java:112)
at restassuredapi.test.StaffUserService.A_01_Test_success(StaffUserService.java:128)
at sun.reflect.NativeMethodAccessorImpl.invoke0(Native Method)
at sun.reflect.NativeMethodAccessorImpl.invoke(Unknown Source)
at sun.reflect.DelegatingMethodAccessorImpl.invoke(Unknown Source)
at java.lang.reflect.Method.invoke(Unknown Source)
at org.testng.internal.MethodInvocationHelper.invokeMethod(MethodInvocationHelper.java:124)
at org.testng.internal.Invoker.invokeMethod(Invoker.java:580)
at org.testng.internal.Invoker.invokeTestMethod(Invoker.java:716)
at org.testng.internal.Invoker.invokeTestMethods(Invoker.java:988)
at org.testng.internal.TestMethodWorker.invokeTestMethods(TestMethodWorker.java:125)
at org.testng.internal.TestMethodWorker.run(TestMethodWorker.java:109)
at org.testng.TestRunner.privateRun(TestRunner.java:648)
at org.testng.TestRunner.run(TestRunner.java:505)
at org.testng.SuiteRunner.runTest(SuiteRunner.java:455)
at org.testng.SuiteRunner.runSequentially(SuiteRunner.java:450)
at org.testng.SuiteRunner.privateRun(SuiteRunner.java:415)
at org.testng.SuiteRunner.run(SuiteRunner.java:364)
at org.testng.SuiteRunnerWorker.runSuite(SuiteRunnerWorker.java:52)
at org.testng.SuiteRunnerWorker.run(SuiteRunnerWorker.java:84)
at org.testng.TestNG.runSuitesSequentially(TestNG.java:1208)
at org.testng.TestNG.runSuitesLocally(TestNG.java:1137)
at org.testng.TestNG.runSuites(TestNG.java:1049)
at org.testng.TestNG.run(TestNG.java:1017)
at org.testng.remote.AbstractRemoteTestNG.run(AbstractRemoteTestNG.java:115)
at org.testng.remote.RemoteTestNG.initAndRun(RemoteTestNG.java:251)
at org.testng.remote.RemoteTestNG.main(RemoteTestNG.java:77)
]]>
    </failure>
  </testcase> <!-- A_01_Test_success -->
  <testcase name="A_01_Test_success" time="1.907" classname="restassuredapi.test.StaffUserService"/>
  <testcase name="A_01_Test_success" time="1.994" classname="restassuredapi.test.StaffUserService"/>
  <testcase name="tearDown" time="106.579" classname="restassuredapi.test.StaffUserService">
    <error type="java.io.FileNotFoundException" message="C:\Users\chetan.chawla\Desktop\BuildID.txt (The system cannot find the path specified)">
      <![CDATA[java.io.FileNotFoundException: C:\Users\chetan.chawla\Desktop\BuildID.txt (The system cannot find the path specified)
at java.io.FileInputStream.open0(Native Method)
at java.io.FileInputStream.open(Unknown Source)
at java.io.FileInputStream.<init>(Unknown Source)
at java.io.FileInputStream.<init>(Unknown Source)
at com.webaut.ctreportutil.util.BuildIDUtil.getBuildID(BuildIDUtil.java:61)
at com.webaut.ctreportutil.CTReporter.BuildIDConfigurator(CTReporter.java:20)
at com.classes.BaseTest.tearDown(BaseTest.java:138)
at sun.reflect.NativeMethodAccessorImpl.invoke0(Native Method)
at sun.reflect.NativeMethodAccessorImpl.invoke(Unknown Source)
at sun.reflect.DelegatingMethodAccessorImpl.invoke(Unknown Source)
at java.lang.reflect.Method.invoke(Unknown Source)
at org.testng.internal.MethodInvocationHelper.invokeMethod(MethodInvocationHelper.java:124)
at org.testng.internal.MethodInvocationHelper.invokeMethodConsideringTimeout(MethodInvocationHelper.java:59)
at org.testng.internal.Invoker.invokeConfigurationMethod(Invoker.java:455)
at org.testng.internal.Invoker.invokeConfigurations(Invoker.java:222)
at org.testng.internal.Invoker.invokeConfigurations(Invoker.java:142)
at org.testng.SuiteRunner.privateRun(SuiteRunner.java:425)
at org.testng.SuiteRunner.run(SuiteRunner.java:364)
at org.testng.SuiteRunnerWorker.runSuite(SuiteRunnerWorker.java:52)
at org.testng.SuiteRunnerWorker.run(SuiteRunnerWorker.java:84)
at org.testng.TestNG.runSuitesSequentially(TestNG.java:1208)
at org.testng.TestNG.runSuitesLocally(TestNG.java:1137)
at org.testng.TestNG.runSuites(TestNG.java:1049)
at org.testng.TestNG.run(TestNG.java:1017)
at org.testng.remote.AbstractRemoteTestNG.run(AbstractRemoteTestNG.java:115)
at org.testng.remote.RemoteTestNG.initAndRun(RemoteTestNG.java:251)
at org.testng.remote.RemoteTestNG.main(RemoteTestNG.java:77)
]]>
    </error>
  </testcase> <!-- tearDown -->
</testsuite> <!-- restassuredapi.test.StaffUserService -->
